<?xml version="1.0" encoding="UTF-8"?>
<sdf version='1.8'>
    <model name='Coaxial Helicopter'>
        <pose>0 0 0 0 0 0</pose>
        <self_collide>false</self_collide>
        <static>false</static>
        <link name='base_link'>
            <pose>0 0 0.5 0 0 0</pose>
            <inertial>
                <mass>2</mass>
                <inertia>
                    <ixx>0.02</ixx>
                    <ixy>0</ixy>
                    <ixz>0</ixz>
                    <iyy>0.02</iyy>
                    <iyz>0</iyz>
                    <izz>0.02</izz>
                </inertia>
            </inertial>
            <gravity>true</gravity>
            <velocity_decay/>
            <visual name='base_link_visual'>
                <pose>0 0 0 0 0 0</pose>
                <geometry>
                    <box>
                        <size>2.0 2.0 0.5</size>
                    </box>
                </geometry>
                <material>
                    <ambient>0.0 0.0 1.0 1</ambient>
                    <diffuse>0.0 0.0 1.0 1</diffuse>
                    <specular>0.0 0.0 1.0 1</specular>
                </material>
            </visual>
            <visual name='swashplate_base_1'>
                <pose>0 0 0.5 0 0 0</pose>
                <geometry>
                    <cylinder>
                        <radius>0.1</radius>
                        <length>1.5</length>
                    </cylinder>
                </geometry>
                <material>
                    <ambient>0.0 1.0 0 1</ambient>
                    <diffuse>0.0 1.0 0 1</diffuse>
                    <specular>0.0 1.0 0 1</specular>
                </material>
            </visual>
            <sensor name="air_pressure_sensor" type="air_pressure">
                <always_on>1</always_on>
                <update_rate>50</update_rate>
                <air_pressure>
                <pressure>
                    <noise type="gaussian">
                    <mean>0</mean>
                    <stddev>0.01</stddev>
                    </noise>
                </pressure>
                </air_pressure>
            </sensor>
            <sensor name="imu_sensor" type="imu">
                <always_on>1</always_on>
                <update_rate>250</update_rate>
                <imu>
                <angular_velocity>
                    <x>
                    <noise type="gaussian">
                        <mean>0</mean>
                        <stddev>0.00018665</stddev>
                        <dynamic_bias_stddev>3.8785e-05</dynamic_bias_stddev>
                        <dynamic_bias_correlation_time>1000</dynamic_bias_correlation_time>
                    </noise>
                    </x>
                    <y>
                    <noise type="gaussian">
                        <mean>0</mean>
                        <stddev>0.00018665</stddev>
                        <dynamic_bias_stddev>3.8785e-05</dynamic_bias_stddev>
                        <dynamic_bias_correlation_time>1000</dynamic_bias_correlation_time>
                    </noise>
                    </y>
                    <z>
                    <noise type="gaussian">
                        <mean>0</mean>
                        <stddev>0.00018665</stddev>
                        <dynamic_bias_stddev>3.8785e-05</dynamic_bias_stddev>
                        <dynamic_bias_correlation_time>1000</dynamic_bias_correlation_time>
                    </noise>
                    </z>
                </angular_velocity>
                <linear_acceleration>
                    <x>
                    <noise type="gaussian">
                        <mean>0</mean>
                        <stddev>0.00186</stddev>
                        <dynamic_bias_stddev>0.006</dynamic_bias_stddev>
                        <dynamic_bias_correlation_time>300</dynamic_bias_correlation_time>
                    </noise>
                    </x>
                    <y>
                    <noise type="gaussian">
                        <mean>0</mean>
                        <stddev>0.00186</stddev>
                        <dynamic_bias_stddev>0.006</dynamic_bias_stddev>
                        <dynamic_bias_correlation_time>300</dynamic_bias_correlation_time>
                    </noise>
                    </y>
                    <z>
                    <noise type="gaussian">
                        <mean>0</mean>
                        <stddev>0.00186</stddev>
                        <dynamic_bias_stddev>0.006</dynamic_bias_stddev>
                        <dynamic_bias_correlation_time>300</dynamic_bias_correlation_time>
                    </noise>
                    </z>
                </linear_acceleration>
                </imu>
            </sensor>
            <sensor name="navsat_sensor" type="navsat">
                <always_on>1</always_on>
                <update_rate>30</update_rate>
            </sensor>
        </link>
        <link name='rotor_0'>
            <pose>0 0 0.85 0 0 0</pose>
            <inertial>
                <pose>0 0 85 0 -0 0</pose>
                <mass>0.005</mass>
                <inertia>
                    <ixx>9.75e-07</ixx>
                    <ixy>0</ixy>
                    <ixz>0</ixz>
                    <iyy>0.000273104</iyy>
                    <iyz>0</iyz>
                    <izz>0.000274004</izz>
                </inertia>
            </inertial>
            <collision name='rotor_0_collision'>
                <pose>0 0 0 0.85 -0 0</pose>
                <geometry>
                    <cylinder>
                        <length>0.005</length>
                        <radius>0.064</radius>
                    </cylinder>
                </geometry>
                <surface>
                    <contact>
                        <ode/>
                    </contact>
                    <friction>
                        <ode/>
                    </friction>
                </surface>
            </collision>
            <visual name='rotor_0_visual'>
                <pose>0 0 0.85 0 0 0</pose>
                <geometry>
                    <cylinder>
                        <length>0.005</length>
                        <radius>1</radius>
                    </cylinder>
                </geometry>
                <material>
                    <ambient>1.0 0.0 0 1</ambient>
                    <diffuse>1.0 0.0 0 1</diffuse>
                    <specular>1.0 0.0 0 1</specular>
                </material>
            </visual>
            <gravity>1</gravity>
            <velocity_decay/>
        </link>
        <joint name='rotor_0_joint' type='revolute'>
            <child>rotor_0</child>
            <parent>base_link</parent>
            <axis>
                <xyz expressed_in="__model__">-0.788675  0.211325   0.57735</xyz>
                <limit>
                    <lower>-1e+16</lower>
                    <upper>1e+16</upper>
                </limit>
                <dynamics>
                    <spring_reference>0</spring_reference>
                    <spring_stiffness>0</spring_stiffness>
                </dynamics>
            </axis>
        </joint>
    </model>
</sdf>